Workbook

Sheet Student
A1: Student ID | B1: Name | C1: Math | D1: Science | E1: English | F1: Enrollment Date | G1: Total | H1: Average | I1: Grade (Nested IF) | J1: Math & Science > 80? | K1: First Name | L1: Name UPPER | M1: Name lower | N1: Years Since Enrollment | O1: Days Since Enrollment | P1: Avg (ROUND) | Q1: Avg (CEILING 5) | R1: Avg (FLOOR 5) | S1: Rank
A2: 1001 | B2: Student 1 | C2: 61 | D2: 48 | E2: 76 | F2: 43101 | G2: =SUM(C2,D2,E2) -> 185 | H2: =AVERAGE(C2,D2,E2) -> 61.666667 | I2: =IF(H2>75,"A",IF(H2>65,"B",IF(H2>55,"C","D"))) -> C | J2: =IF(AND(C2>80,D2>80),"Yes","No") -> No | K2: =LEFT(B3,FIND(" ",B3)-1) -> Student | L2: =UPPER(B2) -> STUDENT 1 | M2: =LOWER(B2) -> student 1 | N2: =IFERROR(IF(F2>"17-Oct-2026","Not yet enrolled",DATEDIF(F2,"16-Oct-2026","Y")),"Not Found") -> 8 | O2: =IFERROR(IF(F2>"17-Oct-2026","Not yet enrolled",DATEDIF(F2,"16-Oct-2026","D")),"Not Found") -> 3210 | P2: =ROUND(H2,0) -> 62 | Q2: =CEILING(H2,5) -> 65 | R2: =FLOOR(H2,5) -> 60 | S2: =RANK(H2,$H$2:$H$21) -> 16
A3: 1002 | B3: Student 2 | C3: 78 | D3: 76 | E3: 70 | F3: 43281 | G3: =SUM(C3,D3,E3) -> 224 | H3: =AVERAGE(C3,D3,E3) -> 74.666667 | I3: =IF(H3>75,"A",IF(H3>65,"B",IF(H3>55,"C","D"))) -> B | J3: =IF(AND(C3>80,D3>80),"Yes","No") -> No | K3: =LEFT(B4,FIND(" ",B4)-1) -> Student | L3: =UPPER(B3) -> STUDENT 2 | M3: =LOWER(B3) -> student 2 | N3: =IFERROR(IF(F3>"17-Oct-2026","Not yet enrolled",DATEDIF(F3,"16-Oct-2026","Y")),"Not Found") -> 8 | O3: =IFERROR(IF(F3>"17-Oct-2026","Not yet enrolled",DATEDIF(F3,"16-Oct-2026","D")),"Not Found") -> 3030 | P3: =ROUND(H3,0) -> 75 | Q3: =CEILING(H3,5) -> 75 | R3: =FLOOR(H3,5) -> 70 | S3: =RANK(H3,$H$2:$H$21) -> 8
A4: 1003 | B4: Student 3 | C4: 97 | D4: 60 | E4: 51 | F4: 43461 | G4: =SUM(C4,D4,E4) -> 208 | H4: =AVERAGE(C4,D4,E4) -> 69.333333 | I4: =IF(H4>75,"A",IF(H4>65,"B",IF(H4>55,"C","D"))) -> B | J4: =IF(AND(C4>80,D4>80),"Yes","No") -> No | K4: =LEFT(B5,FIND(" ",B5)-1) -> Student | L4: =UPPER(B4) -> STUDENT 3 | M4: =LOWER(B4) -> student 3 | N4: =IFERROR(IF(F4>"17-Oct-2026","Not yet enrolled",DATEDIF(F4,"16-Oct-2026","Y")),"Not Found") -> 7 | O4: =IFERROR(IF(F4>"17-Oct-2026","Not yet enrolled",DATEDIF(F4,"16-Oct-2026","D")),"Not Found") -> 2850 | P4: =ROUND(H4,0) -> 69 | Q4: =CEILING(H4,5) -> 70 | R4: =FLOOR(H4,5) -> 65 | S4: =RANK(H4,$H$2:$H$21) -> 12
A5: 1004 | B5: Student 4 | C5: 74 | D5: 55 | E5: 46 | F5: 43641 | G5: =SUM(C5,D5,E5) -> 175 | H5: =AVERAGE(C5,D5,E5) -> 58.333333 | I5: =IF(H5>75,"A",IF(H5>65,"B",IF(H5>55,"C","D"))) -> C | J5: =IF(AND(C5>80,D5>80),"Yes","No") -> No | K5: =LEFT(B6,FIND(" ",B6)-1) -> Student | L5: =UPPER(B5) -> STUDENT 4 | M5: =LOWER(B5) -> student 4 | N5: =IFERROR(IF(F5>"17-Oct-2026","Not yet enrolled",DATEDIF(F5,"16-Oct-2026","Y")),"Not Found") -> 7 | O5: =IFERROR(IF(F5>"17-Oct-2026","Not yet enrolled",DATEDIF(F5,"16-Oct-2026","D")),"Not Found") -> 2670 | P5: =ROUND(H5,0) -> 58 | Q5: =CEILING(H5,5) -> 60 | R5: =FLOOR(H5,5) -> 55 | S5: =RANK(H5,$H$2:$H$21) -> 18
A6: 1005 | B6: Student 5 | C6: 68 | D6: 74 | E6: 84 | F6: 43821 | G6: =SUM(C6,D6,E6) -> 226 | H6: =AVERAGE(C6,D6,E6) -> 75.333333 | I6: =IF(H6>75,"A",IF(H6>65,"B",IF(H6>55,"C","D"))) -> A | J6: =IF(AND(C6>80,D6>80),"Yes","No") -> No | K6: =LEFT(B7,FIND(" ",B7)-1) -> Student | L6: =UPPER(B6) -> STUDENT 5 | M6: =LOWER(B6) -> student 5 | N6: =IFERROR(IF(F6>"17-Oct-2026","Not yet enrolled",DATEDIF(F6,"16-Oct-2026","Y")),"Not Found") -> 6 | O6: =IFERROR(IF(F6>"17-Oct-2026","Not yet enrolled",DATEDIF(F6,"16-Oct-2026","D")),"Not Found") -> 2490 | P6: =ROUND(H6,0) -> 75 | Q6: =CEILING(H6,5) -> 80 | R6: =FLOOR(H6,5) -> 75 | S6: =RANK(H6,$H$2:$H$21) -> 6
A7: 1006 | B7: Student 6 | C7: 80 | D7: 70 | E7: 65 | F7: 44001 | G7: =SUM(C7,D7,E7) -> 215 | H7: =AVERAGE(C7,D7,E7) -> 71.666667 | I7: =IF(H7>75,"A",IF(H7>65,"B",IF(H7>55,"C","D"))) -> B | J7: =IF(AND(C7>80,D7>80),"Yes","No") -> No | K7: =LEFT(B8,FIND(" ",B8)-1) -> Student | L7: =UPPER(B7) -> STUDENT 6 | M7: =LOWER(B7) -> student 6 | N7: =IFERROR(IF(F7>"17-Oct-2026","Not yet enrolled",DATEDIF(F7,"16-Oct-2026","Y")),"Not Found") -> 6 | O7: =IFERROR(IF(F7>"17-Oct-2026","Not yet enrolled",DATEDIF(F7,"16-Oct-2026","D")),"Not Found") -> 2310 | P7: =ROUND(H7,0) -> 72 | Q7: =CEILING(H7,5) -> 75 | R7: =FLOOR(H7,5) -> 70 | S7: =RANK(H7,$H$2:$H$21) -> 9
A8: 1007 | B8: Student 7 | C8: 75 | D8: 47 | E8: 78 | F8: 44181 | G8: =SUM(C8,D8,E8) -> 200 | H8: =AVERAGE(C8,D8,E8) -> 66.666667 | I8: =IF(H8>75,"A",IF(H8>65,"B",IF(H8>55,"C","D"))) -> B | J8: =IF(AND(C8>80,D8>80),"Yes","No") -> No | K8: =LEFT(B9,FIND(" ",B9)-1) -> Student | L8: =UPPER(B8) -> STUDENT 7 | M8: =LOWER(B8) -> student 7 | N8: =IFERROR(IF(F8>"17-Oct-2026","Not yet enrolled",DATEDIF(F8,"16-Oct-2026","Y")),"Not Found") -> 5 | O8: =IFERROR(IF(F8>"17-Oct-2026","Not yet enrolled",DATEDIF(F8,"16-Oct-2026","D")),"Not Found") -> 2130 | P8: =ROUND(H8,0) -> 67 | Q8: =CEILING(H8,5) -> 70 | R8: =FLOOR(H8,5) -> 65 | S8: =RANK(H8,$H$2:$H$21) -> 14
A9: 1008 | B9: Student 8 | C9: 94 | D9: 67 | E9: 64 | F9: 44361 | G9: =SUM(C9,D9,E9) -> 225 | H9: =AVERAGE(C9,D9,E9) -> 75 | I9: =IF(H9>75,"A",IF(H9>65,"B",IF(H9>55,"C","D"))) -> B | J9: =IF(AND(C9>80,D9>80),"Yes","No") -> No | K9: =LEFT(B10,FIND(" ",B10)-1) -> Student | L9: =UPPER(B9) -> STUDENT 8 | M9: =LOWER(B9) -> student 8 | N9: =IFERROR(IF(F9>"17-Oct-2026","Not yet enrolled",DATEDIF(F9,"16-Oct-2026","Y")),"Not Found") -> 5 | O9: =IFERROR(IF(F9>"17-Oct-2026","Not yet enrolled",DATEDIF(F9,"16-Oct-2026","D")),"Not Found") -> 1950 | P9: =ROUND(H9,0) -> 75 | Q9: =CEILING(H9,5) -> 75 | R9: =FLOOR(H9,5) -> 75 | S9: =RANK(H9,$H$2:$H$21) -> 7
A10: 1009 | B10: Student 9 | C10: 41 | D10: 75 | E10: 56 | F10: 44541 | G10: =SUM(C10,D10,E10) -> 172 | H10: =AVERAGE(C10,D10,E10) -> 57.333333 | I10: =IF(H10>75,"A",IF(H10>65,"B",IF(H10>55,"C","D"))) -> C | J10: =IF(AND(C10>80,D10>80),"Yes","No") -> No | K10: =LEFT(B11,FIND(" ",B11)-1) -> Student | L10: =UPPER(B10) -> STUDENT 9 | M10: =LOWER(B10) -> student 9 | N10: =IFERROR(IF(F10>"17-Oct-2026","Not yet enrolled",DATEDIF(F10,"16-Oct-2026","Y")),"Not Found") -> 4 | O10: =IFERROR(IF(F10>"17-Oct-2026","Not yet enrolled",DATEDIF(F10,"16-Oct-2026","D")),"Not Found") -> 1770 | P10: =ROUND(H10,0) -> 57 | Q10: =CEILING(H10,5) -> 60 | R10: =FLOOR(H10,5) -> 55 | S10: =RANK(H10,$H$2:$H$21) -> 19
A11: 1010 | B11: Student 10 | C11: 98 | D11: 54 | E11: 58 | F11: 44721 | G11: =SUM(C11,D11,E11) -> 210 | H11: =AVERAGE(C11,D11,E11) -> 70 | I11: =IF(H11>75,"A",IF(H11>65,"B",IF(H11>55,"C","D"))) -> B | J11: =IF(AND(C11>80,D11>80),"Yes","No") -> No | K11: =LEFT(B12,FIND(" ",B12)-1) -> Student | L11: =UPPER(B11) -> STUDENT 10 | M11: =LOWER(B11) -> student 10 | N11: =IFERROR(IF(F11>"17-Oct-2026","Not yet enrolled",DATEDIF(F11,"16-Oct-2026","Y")),"Not Found") -> 4 | O11: =IFERROR(IF(F11>"17-Oct-2026","Not yet enrolled",DATEDIF(F11,"16-Oct-2026","D")),"Not Found") -> 1590 | P11: =ROUND(H11,0) -> 70 | Q11: =CEILING(H11,5) -> 70 | R11: =FLOOR(H11,5) -> 70 | S11: =RANK(H11,$H$2:$H$21) -> 10
A12: 1011 | B12: Student 11 | C12: 73 | D12: 79 | E12: 53 | F12: 44901 | G12: =SUM(C12,D12,E12) -> 205 | H12: =AVERAGE(C12,D12,E12) -> 68.333333 | I12: =IF(H12>75,"A",IF(H12>65,"B",IF(H12>55,"C","D"))) -> B | J12: =IF(AND(C12>80,D12>80),"Yes","No") -> No | K12: =LEFT(B13,FIND(" ",B13)-1) -> Student | L12: =UPPER(B12) -> STUDENT 11 | M12: =LOWER(B12) -> student 11 | N12: =IFERROR(IF(F12>"17-Oct-2026","Not yet enrolled",DATEDIF(F12,"16-Oct-2026","Y")),"Not Found") -> 3 | O12: =IFERROR(IF(F12>"17-Oct-2026","Not yet enrolled",DATEDIF(F12,"16-Oct-2026","D")),"Not Found") -> 1410 | P12: =ROUND(H12,0) -> 68 | Q12: =CEILING(H12,5) -> 70 | R12: =FLOOR(H12,5) -> 65 | S12: =RANK(H12,$H$2:$H$21) -> 13
A13: 1012 | B13: Student 12 | C13: 85 | D13: 89 | E13: 79 | F13: 45081 | G13: =SUM(C13,D13,E13) -> 253 | H13: =AVERAGE(C13,D13,E13) -> 84.333333 | I13: =IF(H13>75,"A",IF(H13>65,"B",IF(H13>55,"C","D"))) -> A | J13: =IF(AND(C13>80,D13>80),"Yes","No") -> Yes | K13: =LEFT(B14,FIND(" ",B14)-1) -> Student | L13: =UPPER(B13) -> STUDENT 12 | M13: =LOWER(B13) -> student 12 | N13: =IFERROR(IF(F13>"17-Oct-2026","Not yet enrolled",DATEDIF(F13,"16-Oct-2026","Y")),"Not Found") -> 3 | O13: =IFERROR(IF(F13>"17-Oct-2026","Not yet enrolled",DATEDIF(F13,"16-Oct-2026","D")),"Not Found") -> 1230 | P13: =ROUND(H13,0) -> 84 | Q13: =CEILING(H13,5) -> 85 | R13: =FLOOR(H13,5) -> 80 | S13: =RANK(H13,$H$2:$H$21) -> 2
... A20: 1019 | B20: Student 19 | C20: 90 | D20: 78 | E20: 60 | F20: 46341 | G20: =SUM(C20,D20,E20) -> 228 | H20: =AVERAGE(C20,D20,E20) -> 76 | I20: =IF(H20>75,"A",IF(H20>65,"B",IF(H20>55,"C","D"))) -> A | J20: =IF(AND(C20>80,D20>80),"Yes","No") -> No | K20: =LEFT(B21,FIND(" ",B21)-1) -> Student | L20: =UPPER(B20) -> STUDENT 19 | M20: =LOWER(B20) -> student 19 | N20: =IFERROR(IF(F20>"17-Oct-2026","Not yet enrolled",DATEDIF(F20,"16-Oct-2026","Y")),"Not Found") -> Not Found | O20: =IFERROR(IF(F20>"17-Oct-2026","Not yet enrolled",DATEDIF(F20,"16-Oct-2026","D")),"Not Found") -> Not Found | P20: =ROUND(H20,0) -> 76 | Q20: =CEILING(H20,5) -> 80 | R20: =FLOOR(H20,5) -> 75 | S20: =RANK(H20,$H$2:$H$21) -> 5
A21: 1020 | B21: Student 20 | C21: 83 | D21: 92 | E21: 55 | F21: 46521 | G21: =SUM(C21,D21,E21) -> 230 | H21: =AVERAGE(C21,D21,E21) -> 76.666667 | I21: =IF(H21>75,"A",IF(H21>65,"B",IF(H21>55,"C","D"))) -> A | J21: =IF(AND(C21>80,D21>80),"Yes","No") -> Yes | K21: =LEFT(B21,FIND(" ",B21)-1) -> Student | L21: =UPPER(B21) -> STUDENT 20 | M21: =LOWER(B21) -> student 20 | N21: =IFERROR(IF(F21>"17-Oct-2026","Not yet enrolled",DATEDIF(F21,"16-Oct-2026","Y")),"Not Found") -> Not Found | O21: =IFERROR(IF(F21>"17-Oct-2026","Not yet enrolled",DATEDIF(F21,"16-Oct-2026","D")),"Not Found") -> Not Found | P21: =ROUND(H21,0) -> 77 | Q21: =CEILING(H21,5) -> 80 | R21: =FLOOR(H21,5) -> 75 | S21: =RANK(H21,$H$2:$H$21) -> 4

Sheet Sales
A1: Sales ID | B1: Product | C1: Region | D1: Salesperson | E1: Amount | F1: Date | G1: Month | H1: Discount % | I1: Discount Amount | J1: Net Amount | K1: Discount Eligible? | L1: Net (ROUND 100) | M1: Net (CEILING 1000) | N1: Net (FLOOR 1000) | O1: Rolling 3-Sale Avg (OFFSET) | P1: Days Since Prev Sale
A2: 2001 | B2: Keyboard | C2: South | D2: Person 1 | E2: 7048 | F2: 44927 | G2: =TEXT(F2,"mmm") -> Jan | H2: =IF(E2>=30000,"15%",IF(E2>=15000,"10%",IF(E2>=10000,"5%",IF(E2<10000,"2%",0)))) -> 2% | I2: =E2*H2 -> 140.96 | J2: =E2-I2 -> 6907.04 | K2: =IF(OR(B2="Keyboard",E2>=35000),"Yes","No") -> Yes | L2: =ROUND(J2,-2) -> 6900 | M2: =CEILING(J2,1000) -> 7000 | N2: =FLOOR(J2,1000) -> 6000 | O2: =IFERROR(AVERAGE(OFFSET(E2,-2,0,3,1)),"Not Working") -> Not Working | P2: Not Working
A3: 2002 | B3: Printer | C3: West | D3: Person 2 | E3: 17428 | F3: 44942 | G3: =TEXT(F3,"mmm") -> Jan | H3: =IF(E3>=30000,"15%",IF(E3>=15000,"10%",IF(E3>=10000,"5%",IF(E3<10000,"2%",0)))) -> 10% | I3: =E3*H3 -> 1742.8 | J3: =E3-I3 -> 15685.2 | K3: =IF(OR(B3="Keyboard",E3>=35000),"Yes","No") -> No | L3: =ROUND(J3,-2) -> 15700 | M3: =CEILING(J3,1000) -> 16000 | N3: =FLOOR(J3,1000) -> 15000 | O3: =IFERROR(AVERAGE(OFFSET(E3,-2,0,3,1)),"Not Working") -> 12238 | P3: =F3-F2 -> 15
A4: 2003 | B4: Mouse | C4: South | D4: Person 3 | E4: 23672 | F4: 44957 | G4: =TEXT(F4,"mmm") -> Jan | H4: =IF(E4>=30000,"15%",IF(E4>=15000,"10%",IF(E4>=10000,"5%",IF(E4<10000,"2%",0)))) -> 10% | I4: =E4*H4 -> 2367.2 | J4: =E4-I4 -> 21304.8 | K4: =IF(OR(B4="Keyboard",E4>=35000),"Yes","No") -> No | L4: =ROUND(J4,-2) -> 21300 | M4: =CEILING(J4,1000) -> 22000 | N4: =FLOOR(J4,1000) -> 21000 | O4: =IFERROR(AVERAGE(OFFSET(E4,-2,0,3,1)),"Not Working") -> 16049.333 | P4: =F4-F3 -> 15
A5: 2004 | B5: Printer | C5: East | D5: Person 4 | E5: 5264 | F5: 44972 | G5: =TEXT(F5,"mmm") -> Feb | H5: =IF(E5>=30000,"15%",IF(E5>=15000,"10%",IF(E5>=10000,"5%",IF(E5<10000,"2%",0)))) -> 2% | I5: =E5*H5 -> 105.28 | J5: =E5-I5 -> 5158.72 | K5: =IF(OR(B5="Keyboard",E5>=35000),"Yes","No") -> No | L5: =ROUND(J5,-2) -> 5200 | M5: =CEILING(J5,1000) -> 6000 | N5: =FLOOR(J5,1000) -> 5000 | O5: =IFERROR(AVERAGE(OFFSET(E5,-2,0,3,1)),"Not Working") -> 15454.667 | P5: =F5-F4 -> 15
A6: 2005 | B6: Keyboard | C6: North | D6: Person 5 | E6: 43388 | F6: 44987 | G6: =TEXT(F6,"mmm") -> Mar | H6: =IF(E6>=30000,"15%",IF(E6>=15000,"10%",IF(E6>=10000,"5%",IF(E6<10000,"2%",0)))) -> 15% | I6: =E6*H6 -> 6508.2 | J6: =E6-I6 -> 36879.8 | K6: =IF(OR(B6="Keyboard",E6>=35000),"Yes","No") -> Yes | L6: =ROUND(J6,-2) -> 36900 | M6: =CEILING(J6,1000) -> 37000 | N6: =FLOOR(J6,1000) -> 36000 | O6: =IFERROR(AVERAGE(OFFSET(E6,-2,0,3,1)),"Not Working") -> 24108 | P6: =F6-F5 -> 15
A7: 2006 | B7: Mouse | C7: North | D7: Person 6 | E7: 19757 | F7: 45002 | G7: =TEXT(F7,"mmm") -> Mar | H7: =IF(E7>=30000,"15%",IF(E7>=15000,"10%",IF(E7>=10000,"5%",IF(E7<10000,"2%",0)))) -> 10% | I7: =E7*H7 -> 1975.7 | J7: =E7-I7 -> 17781.3 | K7: =IF(OR(B7="Keyboard",E7>=35000),"Yes","No") -> No | L7: =ROUND(J7,-2) -> 17800 | M7: =CEILING(J7,1000) -> 18000 | N7: =FLOOR(J7,1000) -> 17000 | O7: =IFERROR(AVERAGE(OFFSET(E7,-2,0,3,1)),"Not Working") -> 22803 | P7: =F7-F6 -> 15
A8: 2007 | B8: Mouse | C8: East | D8: Person 7 | E8: 32058 | F8: 45017 | G8: =TEXT(F8,"mmm") -> Apr | H8: =IF(E8>=30000,"15%",IF(E8>=15000,"10%",IF(E8>=10000,"5%",IF(E8<10000,"2%",0)))) -> 15% | I8: =E8*H8 -> 4808.7 | J8: =E8-I8 -> 27249.3 | K8: =IF(OR(B8="Keyboard",E8>=35000),"Yes","No") -> No | L8: =ROUND(J8,-2) -> 27200 | M8: =CEILING(J8,1000) -> 28000 | N8: =FLOOR(J8,1000) -> 27000 | O8: =IFERROR(AVERAGE(OFFSET(E8,-2,0,3,1)),"Not Working") -> 31734.333 | P8: =F8-F7 -> 15
A9: 2008 | B9: Keyboard | C9: East | D9: Person 8 | E9: 46429 | F9: 45032 | G9: =TEXT(F9,"mmm") -> Apr | H9: =IF(E9>=30000,"15%",IF(E9>=15000,"10%",IF(E9>=10000,"5%",IF(E9<10000,"2%",0)))) -> 15% | I9: =E9*H9 -> 6964.35 | J9: =E9-I9 -> 39464.65 | K9: =IF(OR(B9="Keyboard",E9>=35000),"Yes","No") -> Yes | L9: =ROUND(J9,-2) -> 39500 | M9: =CEILING(J9,1000) -> 40000 | N9: =FLOOR(J9,1000) -> 39000 | O9: =IFERROR(AVERAGE(OFFSET(E9,-2,0,3,1)),"Not Working") -> 32748 | P9: =F9-F8 -> 15
A10: 2009 | B10: Printer | C10: East | D10: Person 9 | E10: 19746 | F10: 45047 | G10: =TEXT(F10,"mmm") -> May | H10: =IF(E10>=30000,"15%",IF(E10>=15000,"10%",IF(E10>=10000,"5%",IF(E10<10000,"2%",0)))) -> 10% | I10: =E10*H10 -> 1974.6 | J10: =E10-I10 -> 17771.4 | K10: =IF(OR(B10="Keyboard",E10>=35000),"Yes","No") -> No | L10: =ROUND(J10,-2) -> 17800 | M10: =CEILING(J10,1000) -> 18000 | N10: =FLOOR(J10,1000) -> 17000 | O10: =IFERROR(AVERAGE(OFFSET(E10,-2,0,3,1)),"Not Working") -> 32744.333 | P10: =F10-F9 -> 15
A11: 2010 | B11: Keyboard | C11: South | D11: Person 10 | E11: 35185 | F11: 45062 | G11: =TEXT(F11,"mmm") -> May | H11: =IF(E11>=30000,"15%",IF(E11>=15000,"10%",IF(E11>=10000,"5%",IF(E11<10000,"2%",0)))) -> 15% | I11: =E11*H11 -> 5277.75 | J11: =E11-I11 -> 29907.25 | K11: =IF(OR(B11="Keyboard",E11>=35000),"Yes","No") -> Yes | L11: =ROUND(J11,-2) -> 29900 | M11: =CEILING(J11,1000) -> 30000 | N11: =FLOOR(J11,1000) -> 29000 | O11: =IFERROR(AVERAGE(OFFSET(E11,-2,0,3,1)),"Not Working") -> 33786.667 | P11: =F11-F10 -> 15
A12: 2011 | B12: Keyboard | C12: East | D12: Person 11 | E12: 33920 | F12: 45077 | G12: =TEXT(F12,"mmm") -> May | H12: =IF(E12>=30000,"15%",IF(E12>=15000,"10%",IF(E12>=10000,"5%",IF(E12<10000,"2%",0)))) -> 15% | I12: =E12*H12 -> 5088 | J12: =E12-I12 -> 28832 | K12: =IF(OR(B12="Keyboard",E12>=35000),"Yes","No") -> Yes | L12: =ROUND(J12,-2) -> 28800 | M12: =CEILING(J12,1000) -> 29000 | N12: =FLOOR(J12,1000) -> 28000 | O12: =IFERROR(AVERAGE(OFFSET(E12,-2,0,3,1)),"Not Working") -> 29617 | P12: =F12-F11 -> 15
A13: 2012 | B13: Monitor | C13: North | D13: Person 12 | E13: 35611 | F13: 45092 | G13: =TEXT(F13,"mmm") -> Jun | H13: =IF(E13>=30000,"15%",IF(E13>=15000,"10%",IF(E13>=10000,"5%",IF(E13<10000,"2%",0)))) -> 15% | I13: =E13*H13 -> 5341.65 | J13: =E13-I13 -> 30269.35 | K13: =IF(OR(B13="Keyboard",E13>=35000),"Yes","No") -> Yes | L13: =ROUND(J13,-2) -> 30300 | M13: =CEILING(J13,1000) -> 31000 | N13: =FLOOR(J13,1000) -> 30000 | O13: =IFERROR(AVERAGE(OFFSET(E13,-2,0,3,1)),"Not Working") -> 34905.333 | P13: =F13-F12 -> 15
A14: 2013 | B14: Laptop | C14: East | D14: Person 13 | E14: 15560 | F14: 45107 | G14: =TEXT(F14,"mmm") -> Jun | H14: =IF(E14>=30000,"15%",IF(E14>=15000,"10%",IF(E14>=10000,"5%",IF(E14<10000,"2%",0)))) -> 10% | I14: =E14*H14 -> 1556 | J14: =E14-I14 -> 14004 | K14: =IF(OR(B14="Keyboard",E14>=35000),"Yes","No") -> No | L14: =ROUND(J14,-2) -> 14000 | M14: =CEILING(J14,1000) -> 15000 | N14: =FLOOR(J14,1000) -> 14000 | O14: =IFERROR(AVERAGE(OFFSET(E14,-2,0,3,1)),"Not Working") -> 28363.667 | P14: =F14-F13 -> 15
... A21: 2020 | B21: Printer | C21: West | D21: Person 20 | E21: 33953 | F21: 45212 | G21: =TEXT(F21,"mmm") -> Oct | H21: =IF(E21>=30000,"15%",IF(E21>=15000,"10%",IF(E21>=10000,"5%",IF(E21<10000,"2%",0)))) -> 15% | I21: =E21*H21 -> 5092.95 | J21: =E21-I21 -> 28860.05 | K21: =IF(OR(B21="Keyboard",E21>=35000),"Yes","No") -> No | L21: =ROUND(J21,-2) -> 28900 | M21: =CEILING(J21,1000) -> 29000 | N21: =FLOOR(J21,1000) -> 28000 | O21: =IFERROR(AVERAGE(OFFSET(E21,-2,0,3,1)),"Not Working") -> 34183.333 | P21: =F21-F20 -> 15

Sheet Employee
A1: Employee ID | B1: Name | C1: Department | D1: Salary | E1: Joining Date | F1: Status | G1: Tenure (Years) | H1: Joining Date (Long) | I1: Joining Weekday | J1: Salary Band (Nested IF) | K1: Bonus | L1: Bonus (ROUND 100) | M1: Name UPPER | N1: Days Since Joining | O1: Senior Track? (AND/OR)
A2: 3001 | B2: Employee 1 | C2: Finance | D2: 86766 | E2: 42005 | F2: =IF(E2>DATE(2026,10,23),"Upcoming","Active") -> Active | G2: =IF(E2>DATE(2026,10,23),0,ROUND(YEARFRAC(E2,DATE(2026,10,23),1),1)) -> 11.8 | H2: =TEXT(E2,"dd mmmm yyyy") -> 01 January 2015 | I2: =TEXT(E2,"dddd") -> Thursday | J2: =IF(D2>=100000,"High",IF(D2>=60000,"Mid","Entry")) -> Mid | K2: =D2*10% -> 8676.6 | L2: =ROUND(K2,-2) -> 8700 | M2: =UPPER(B2) -> EMPLOYEE 1 | N2: =IF(E2>DATE(2026,10,23),"Upcoming",DATE(2026,10,23)-E2) -> 4313 | O2: =IF(AND(G2>=5,OR(C2="IT",C2="Finance")),"Yes","No") -> Yes
A3: 3002 | B3: Employee 2 | C3: Finance | D3: 31943 | E3: 42255 | F3: =IF(E3>DATE(2026,10,23),"Upcoming","Active") -> Active | G3: =IF(E3>DATE(2026,10,23),0,ROUND(YEARFRAC(E3,DATE(2026,10,23),1),1)) -> 11.1 | H3: =TEXT(E3,"dd mmmm yyyy") -> 08 September 2015 | I3: =TEXT(E3,"dddd") -> Tuesday | J3: =IF(D3>=100000,"High",IF(D3>=60000,"Mid","Entry")) -> Entry | K3: =D3*10% -> 3194.3 | L3: =ROUND(K3,-2) -> 3200 | M3: =UPPER(B3) -> EMPLOYEE 2 | N3: =IF(E3>DATE(2026,10,23),"Upcoming",DATE(2026,10,23)-E3) -> 4063 | O3: =IF(AND(G3>=5,OR(C3="IT",C3="Finance")),"Yes","No") -> Yes
A4: 3003 | B4: Employee 3 | C4: HR | D4: 63374 | E4: 42505 | F4: =IF(E4>DATE(2026,10,23),"Upcoming","Active") -> Active | G4: =IF(E4>DATE(2026,10,23),0,ROUND(YEARFRAC(E4,DATE(2026,10,23),1),1)) -> 10.4 | H4: =TEXT(E4,"dd mmmm yyyy") -> 15 May 2016 | I4: =TEXT(E4,"dddd") -> Sunday | J4: =IF(D4>=100000,"High",IF(D4>=60000,"Mid","Entry")) -> Mid | K4: =D4*10% -> 6337.4 | L4: =ROUND(K4,-2) -> 6300 | M4: =UPPER(B4) -> EMPLOYEE 3 | N4: =IF(E4>DATE(2026,10,23),"Upcoming",DATE(2026,10,23)-E4) -> 3813 | O4: =IF(AND(G4>=5,OR(C4="IT",C4="Finance")),"Yes","No") -> No
A5: 3004 | B5: Employee 4 | C5: Finance | D5: 109972 | E5: 42755 | F5: =IF(E5>DATE(2026,10,23),"Upcoming","Active") -> Active | G5: =IF(E5>DATE(2026,10,23),0,ROUND(YEARFRAC(E5,DATE(2026,10,23),1),1)) -> 9.8 | H5: =TEXT(E5,"dd mmmm yyyy") -> 20 January 2017 | I5: =TEXT(E5,"dddd") -> Friday | J5: =IF(D5>=100000,"High",IF(D5>=60000,"Mid","Entry")) -> High | K5: =D5*10% -> 10997.2 | L5: =ROUND(K5,-2) -> 11000 | M5: =UPPER(B5) -> EMPLOYEE 4 | N5: =IF(E5>DATE(2026,10,23),"Upcoming",DATE(2026,10,23)-E5) -> 3563 | O5: =IF(AND(G5>=5,OR(C5="IT",C5="Finance")),"Yes","No") -> Yes
A6: 3005 | B6: Employee 5 | C6: IT | D6: 54149 | E6: 43005 | F6: =IF(E6>DATE(2026,10,23),"Upcoming","Active") -> Active | G6: =IF(E6>DATE(2026,10,23),0,ROUND(YEARFRAC(E6,DATE(2026,10,23),1),1)) -> 9.1 | H6: =TEXT(E6,"dd mmmm yyyy") -> 27 September 2017 | I6: =TEXT(E6,"dddd") -> Wednesday | J6: =IF(D6>=100000,"High",IF(D6>=60000,"Mid","Entry")) -> Entry | K6: =D6*10% -> 5414.9 | L6: =ROUND(K6,-2) -> 5400 | M6: =UPPER(B6) -> EMPLOYEE 5 | N6: =IF(E6>DATE(2026,10,23),"Upcoming",DATE(2026,10,23)-E6) -> 3313 | O6: =IF(AND(G6>=5,OR(C6="IT",C6="Finance")),"Yes","No") -> Yes
A7: 3006 | B7: Employee 6 | C7: IT | D7: 78689 | E7: 43255 | F7: =IF(E7>DATE(2026,10,23),"Upcoming","Active") -> Active | G7: =IF(E7>DATE(2026,10,23),0,ROUND(YEARFRAC(E7,DATE(2026,10,23),1),1)) -> 8.4 | H7: =TEXT(E7,"dd mmmm yyyy") -> 04 June 2018 | I7: =TEXT(E7,"dddd") -> Monday | J7: =IF(D7>=100000,"High",IF(D7>=60000,"Mid","Entry")) -> Mid | K7: =D7*10% -> 7868.9 | L7: =ROUND(K7,-2) -> 7900 | M7: =UPPER(B7) -> EMPLOYEE 6 | N7: =IF(E7>DATE(2026,10,23),"Upcoming",DATE(2026,10,23)-E7) -> 3063 | O7: =IF(AND(G7>=5,OR(C7="IT",C7="Finance")),"Yes","No") -> Yes
A8: 3007 | B8: Employee 7 | C8: Marketing | D8: 35960 | E8: 43505 | F8: =IF(E8>DATE(2026,10,23),"Upcoming","Active") -> Active | G8: =IF(E8>DATE(2026,10,23),0,ROUND(YEARFRAC(E8,DATE(2026,10,23),1),1)) -> 7.7 | H8: =TEXT(E8,"dd mmmm yyyy") -> 09 February 2019 | I8: =TEXT(E8,"dddd") -> Saturday | J8: =IF(D8>=100000,"High",IF(D8>=60000,"Mid","Entry")) -> Entry | K8: =D8*10% -> 3596 | L8: =ROUND(K8,-2) -> 3600 | M8: =UPPER(B8) -> EMPLOYEE 7 | N8: =IF(E8>DATE(2026,10,23),"Upcoming",DATE(2026,10,23)-E8) -> 2813 | O8: =IF(AND(G8>=5,OR(C8="IT",C8="Finance")),"Yes","No") -> No
A9: 3008 | B9: Employee 8 | C9: IT | D9: 91659 | E9: 43755 | F9: =IF(E9>DATE(2026,10,23),"Upcoming","Active") -> Active | G9: =IF(E9>DATE(2026,10,23),0,ROUND(YEARFRAC(E9,DATE(2026,10,23),1),1)) -> 7 | H9: =TEXT(E9,"dd mmmm yyyy") -> 17 October 2019 | I9: =TEXT(E9,"dddd") -> Thursday | J9: =IF(D9>=100000,"High",IF(D9>=60000,"Mid","Entry")) -> Mid | K9: =D9*10% -> 9165.9 | L9: =ROUND(K9,-2) -> 9200 | M9: =UPPER(B9) -> EMPLOYEE 8 | N9: =IF(E9>DATE(2026,10,23),"Upcoming",DATE(2026,10,23)-E9) -> 2563 | O9: =IF(AND(G9>=5,OR(C9="IT",C9="Finance")),"Yes","No") -> Yes
A10: 3009 | B10: Employee 9 | C10: IT | D10: 90423 | E10: 44005 | F10: =IF(E10>DATE(2026,10,23),"Upcoming","Active") -> Active | G10: =IF(E10>DATE(2026,10,23),0,ROUND(YEARFRAC(E10,DATE(2026,10,23),1),1)) -> 6.3 | H10: =TEXT(E10,"dd mmmm yyyy") -> 23 June 2020 | I10: =TEXT(E10,"dddd") -> Tuesday | J10: =IF(D10>=100000,"High",IF(D10>=60000,"Mid","Entry")) -> Mid | K10: =D10*10% -> 9042.3 | L10: =ROUND(K10,-2) -> 9000 | M10: =UPPER(B10) -> EMPLOYEE 9 | N10: =IF(E10>DATE(2026,10,23),"Upcoming",DATE(2026,10,23)-E10) -> 2313 | O10: =IF(AND(G10>=5,OR(C10="IT",C10="Finance")),"Yes","No") -> Yes
A11: 3010 | B11: Employee 10 | C11: HR | D11: 107877 | E11: 44255 | F11: =IF(E11>DATE(2026,10,23),"Upcoming","Active") -> Active | G11: =IF(E11>DATE(2026,10,23),0,ROUND(YEARFRAC(E11,DATE(2026,10,23),1),1)) -> 5.6 | H11: =TEXT(E11,"dd mmmm yyyy") -> 28 February 2021 | I11: =TEXT(E11,"dddd") -> Sunday | J11: =IF(D11>=100000,"High",IF(D11>=60000,"Mid","Entry")) -> High | K11: =D11*10% -> 10787.7 | L11: =ROUND(K11,-2) -> 10800 | M11: =UPPER(B11) -> EMPLOYEE 10 | N11: =IF(E11>DATE(2026,10,23),"Upcoming",DATE(2026,10,23)-E11) -> 2063 | O11: =IF(AND(G11>=5,OR(C11="IT",C11="Finance")),"Yes","No") -> No
A12: 3011 | B12: Employee 11 | C12: Finance | D12: 107634 | E12: 44505 | F12: =IF(E12>DATE(2026,10,23),"Upcoming","Active") -> Active | G12: =IF(E12>DATE(2026,10,23),0,ROUND(YEARFRAC(E12,DATE(2026,10,23),1),1)) -> 5 | H12: =TEXT(E12,"dd mmmm yyyy") -> 05 November 2021 | I12: =TEXT(E12,"dddd") -> Friday | J12: =IF(D12>=100000,"High",IF(D12>=60000,"Mid","Entry")) -> High | K12: =D12*10% -> 10763.4 | L12: =ROUND(K12,-2) -> 10800 | M12: =UPPER(B12) -> EMPLOYEE 11 | N12: =IF(E12>DATE(2026,10,23),"Upcoming",DATE(2026,10,23)-E12) -> 1813 | O12: =IF(AND(G12>=5,OR(C12="IT",C12="Finance")),"Yes","No") -> Yes
A13: 3012 | B13: Employee 12 | C13: Finance | D13: 35226 | E13: 44755 | F13: =IF(E13>DATE(2026,10,23),"Upcoming","Active") -> Active | G13: =IF(E13>DATE(2026,10,23),0,ROUND(YEARFRAC(E13,DATE(2026,10,23),1),1)) -> 4.3 | H13: =TEXT(E13,"dd mmmm yyyy") -> 13 July 2022 | I13: =TEXT(E13,"dddd") -> Wednesday | J13: =IF(D13>=100000,"High",IF(D13>=60000,"Mid","Entry")) -> Entry | K13: =D13*10% -> 3522.6 | L13: =ROUND(K13,-2) -> 3500 | M13: =UPPER(B13) -> EMPLOYEE 12 | N13: =IF(E13>DATE(2026,10,23),"Upcoming",DATE(2026,10,23)-E13) -> 1563 | O13: =IF(AND(G13>=5,OR(C13="IT",C13="Finance")),"Yes","No") -> No
... A21: 3020 | B21: Employee 20 | C21: Marketing | D21: 99924 | E21: 46755 | F21: =IF(E21>DATE(2026,10,23),"Upcoming","Active") -> Upcoming | G21: =IF(E21>DATE(2026,10,23),0,ROUND(YEARFRAC(E21,DATE(2026,10,23),1),1)) -> 0 | H21: =TEXT(E21,"dd mmmm yyyy") -> 03 January 2028 | I21: =TEXT(E21,"dddd") -> Monday | J21: =IF(D21>=100000,"High",IF(D21>=60000,"Mid","Entry")) -> Mid | K21: =D21*10% -> 9992.4 | L21: =ROUND(K21,-2) -> 10000 | M21: =UPPER(B21) -> EMPLOYEE 20 | N21: =IF(E21>DATE(2026,10,23),"Upcoming",DATE(2026,10,23)-E21) -> Upcoming | O21: =IF(AND(G21>=5,OR(C21="IT",C21="Finance")),"Yes","No") -> No

Sheet Pivot-Table
A1: Pivot - Tables
A3: Sum Of Sales by Product and Region
A4: Sales | B4: Product
A5: Region | B5: Keyboard | C5: Laptop | D5: Monitor | E5: Mouse | F5: Printer | G5: Grand Total
A6: East | B6: 80349 | C6: 31238 | E6: 37335 | F6: 25010 | G6: 173932
A7: North | B7: 43388 | D7: 77482 | E7: 19757 | G7: 140627
A8: South | B8: 42233 | C8: 7283 | E8: 23672 | G8: 73188
A9: West | D9: 38161 | E9: 30436 | F9: 51381 | G9: 119978
A10: Grand Total | B10: 165970 | C10: 38521 | D10: 115643 | E10: 111200 | F10: 76391 | G10: 507725
A12: Sum Of Sales, Discount and Net Amount By Product
A13: Products | B13: Amounts | C13: Discount Amounts | D13: Net Amounts
A14: Keyboard | B14: 165970 | C14: 23979.26 | D14: 141990.74
A15: Laptop | B15: 38521 | C15: 3269.46 | D15: 35251.54
A16: Monitor | B16: 115643 | C16: 17346.45 | D16: 98296.55
A17: Mouse | B17: 111200 | C17: 13822.54 | D17: 97377.46
A18: Printer | B18: 76391 | C18: 8915.63 | D18: 67475.37
A19: Grand Total | B19: 507725 | C19: 67333.34 | D19: 440391.66
A21: Sum Of Sales,Discount And Net Amount By Region
A22: Region | B22: Sum of Amount | C22: Sum of Discount Amount | D22: Sum of Net Amount
A23: East | B23: 173932 | C23: 22170.27 | D23: 151761.73
A24: North | B24: 140627 | C24: 20106.2 | D24: 120520.8
A25: South | B25: 73188 | C25: 7931.57 | D25: 65256.43
A26: West | B26: 119978 | C26: 17125.3 | D26: 102852.7
A27: Grand Total | B27: 507725 | C27: 67333.34 | D27: 440391.66
A29: Sum Of Salary By Department & Salary Band
A30: Count of Name | B30: Salary Band
A31: Department | B31: Entry | C31: High | D31: Mid | E31: Grand Total
A32: Finance | B32: 2 | C32: 3 | D32: 1 | E32: 6
A33: HR | B33: 2 | C33: 1 | D33: 3 | E33: 6
A34: IT | B34: 1 | C34: 1 | D34: 3 | E34: 5
A35: Marketing | B35: 1 | C35: 1 | D35: 1 | E35: 3
A36: Grand Total | B36: 6 | C36: 6 | D36: 8 | E36: 20
A38: Count Of Student By Grade
A39: Grades | B39: Number Of Student
A40: A | B40: 6
A41: B | B41: 9
A42: C | B42: 4
A43: D | B43: 1
A44: Grand Total | B44: 20
A46: Student Rank By Average According To ID
...

Sheet Analysis
A1: Analysis - Sales , Student & Employee | D1: Charts
A3: Sales
A4: Total sales | B4: =SUM(Sales!E2:E21) -> 507725
A5: Number of sales | B5: =COUNT(Sales!A2:A21) -> 20
A6: Average sale | B6: =AVERAGE(Sales!E2:E21) -> 25386.25
A7: Largest sale | B7: =MAX(Sales!E2:E21) -> 46429
A8: Total discount given | B8: =SUM(Sales!I2:I21) -> 67333.34
A9: Net revenue after discount | B9: =SUM(Sales!J2:J21) -> 440391.66
A10: Sales eligible for discount | B10: =COUNTIF(Sales!K2:K21,"Yes") -> 8
A12: Employees
A13: Headcount | B13: =COUNT(Employee!A2:A21) -> 20
A14: Total payroll | B14: =SUM(Employee!D2:D21) -> 1586798
A15: Average salary | B15: =AVERAGE(Employee!D2:D21) -> 79339.9
A16: Highest salary | B16: =MAX(Sales!E2:E21) -> 46429
A17: Employees in High band | B17: =COUNTIF(Employee!J2:J21,"High") -> 6
A19: Students
A20: Number of students | B20: =COUNT(Student!A2:A21) -> 20
A21: Average Math | B21: =AVERAGE(Student!C2:C21) -> 80.2
A22: Average Science | B22: =AVERAGE(Student!D2:D21) -> 66.45
A23: Average English | B23: =AVERAGE(Student!E2:E21) -> 64.5
A24: Top student average | B24: =MAX(Student!H2:H21) -> 95
